Workbook

Sheet Summary
A1: Cisco Partner Rehberi — Phase 1 dataset audit
A2: Audit of the 7 SelectorTool CSVs, 9 Oct 2026. Lifecycle checked against Cisco/Meraki EoL pages listed on the Lifecycle tab.
A4: Issues by file and severity
A5: File | B5: Rows in file | C5: High | D5: Medium | E5: Low | F5: Total | G5: Open
A6: switching.csv | B6: 357 | C6: =COUNTIFS(Issues!$B$2:$B$349,$A6,Issues!$F$2:$F$349,"High") -> 19 | D6: =COUNTIFS(Issues!$B$2:$B$349,$A6,Issues!$F$2:$F$349,"Medium") -> 36 | E6: =COUNTIFS(Issues!$B$2:$B$349,$A6,Issues!$F$2:$F$349,"Low") -> 25 | F6: =SUM(C6:E6) -> 80 | G6: =COUNTIFS(Issues!$B$2:$B$349,$A6,Issues!$J$2:$J$349,"<>Fixed") -> 80
A7: wireless-data.csv | B7: 47 | C7: =COUNTIFS(Issues!$B$2:$B$349,$A7,Issues!$F$2:$F$349,"High") -> 1 | D7: =COUNTIFS(Issues!$B$2:$B$349,$A7,Issues!$F$2:$F$349,"Medium") -> 25 | E7: =COUNTIFS(Issues!$B$2:$B$349,$A7,Issues!$F$2:$F$349,"Low") -> 11 | F7: =SUM(C7:E7) -> 37 | G7: =COUNTIFS(Issues!$B$2:$B$349,$A7,Issues!$J$2:$J$349,"<>Fixed") -> 37
A8: wireless-antenna-data.csv | B8: 117 | C8: =COUNTIFS(Issues!$B$2:$B$349,$A8,Issues!$F$2:$F$349,"High") -> 1 | D8: =COUNTIFS(Issues!$B$2:$B$349,$A8,Issues!$F$2:$F$349,"Medium") -> 11 | E8: =COUNTIFS(Issues!$B$2:$B$349,$A8,Issues!$F$2:$F$349,"Low") -> 32 | F8: =SUM(C8:E8) -> 44 | G8: =COUNTIFS(Issues!$B$2:$B$349,$A8,Issues!$J$2:$J$349,"<>Fixed") -> 44
A9: routers.csv | B9: 165 | C9: =COUNTIFS(Issues!$B$2:$B$349,$A9,Issues!$F$2:$F$349,"High") -> 38 | D9: =COUNTIFS(Issues!$B$2:$B$349,$A9,Issues!$F$2:$F$349,"Medium") -> 50 | E9: =COUNTIFS(Issues!$B$2:$B$349,$A9,Issues!$F$2:$F$349,"Low") -> 13 | F9: =SUM(C9:E9) -> 101 | G9: =COUNTIFS(Issues!$B$2:$B$349,$A9,Issues!$J$2:$J$349,"<>Fixed") -> 101
A10: router-modules.csv | B10: 27 | C10: =COUNTIFS(Issues!$B$2:$B$349,$A10,Issues!$F$2:$F$349,"High") -> 28 | D10: =COUNTIFS(Issues!$B$2:$B$349,$A10,Issues!$F$2:$F$349,"Medium") -> 11 | E10: =COUNTIFS(Issues!$B$2:$B$349,$A10,Issues!$F$2:$F$349,"Low") -> 0 | F10: =SUM(C10:E10) -> 39 | G10: =COUNTIFS(Issues!$B$2:$B$349,$A10,Issues!$J$2:$J$349,"<>Fixed") -> 39
A11: DC-data.csv | B11: 60 | C11: =COUNTIFS(Issues!$B$2:$B$349,$A11,Issues!$F$2:$F$349,"High") -> 28 | D11: =COUNTIFS(Issues!$B$2:$B$349,$A11,Issues!$F$2:$F$349,"Medium") -> 8 | E11: =COUNTIFS(Issues!$B$2:$B$349,$A11,Issues!$F$2:$F$349,"Low") -> 1 | F11: =SUM(C11:E11) -> 37 | G11: =COUNTIFS(Issues!$B$2:$B$349,$A11,Issues!$J$2:$J$349,"<>Fixed") -> 37
A12: dc-modules-data.csv | B12: 39 | C12: =COUNTIFS(Issues!$B$2:$B$349,$A12,Issues!$F$2:$F$349,"High") -> 3 | D12: =COUNTIFS(Issues!$B$2:$B$349,$A12,Issues!$F$2:$F$349,"Medium") -> 4 | E12: =COUNTIFS(Issues!$B$2:$B$349,$A12,Issues!$F$2:$F$349,"Low") -> 3 | F12: =SUM(C12:E12) -> 10 | G12: =COUNTIFS(Issues!$B$2:$B$349,$A12,Issues!$J$2:$J$349,"<>Fixed") -> 10
A13: Total | B13: =SUM(B6:B12) -> 812 | C13: =SUM(C6:C12) -> 118 | D13: =SUM(D6:D12) -> 145 | E13: =SUM(E6:E12) -> 85 | F13: =SUM(F6:F12) -> 348 | G13: =SUM(G6:G12) -> 348
A15: Lifecycle actions (Lifecycle tab)
A16: Action | B16: Groups
A17: Remove… | B17: =COUNTIF(Lifecycle!$G$2:$G$33,"Remove*") -> 10
A18: Keep with badge… | B18: =COUNTIF(Lifecycle!$G$2:$G$33,"Keep with badge*") -> 12
A19: Verify / re-check / fill… | B19: =COUNTIF(Lifecycle!$G$2:$G$33,"Verify*")+COUNTIF(Lifecycle!$G$2:$G$33,"Re-check*")+COUNTIF(Lifecycle!$G$2:$G$33,"Fill*") -> 5
A20: Keep (current) | B20: =COUNTIF(Lifecycle!$G$2:$G$33,"Keep")+COUNTIF(Lifecycle!$G$2:$G$33,"Keep;*") -> 5
A23: How to use
A24: Issues tab: one row per problem. Set Status (yellow column) to Open / Fixed / Won't fix; the Open counts above update.
A25: CSV row = line number in the CSV file (header is line 1). Blank = applies to many rows; see Model / scope.
A26: Severity: High = wrong advice or a model hidden from users; Medium = misleading or incomplete; Low = hygiene.
A27: Filter tests tab: what the old filter code does with this data. These go away once the new schema stores clean values.
A28: Lifecycle "Not verified" rows still need a check on cisco.com before Phase 3.

Sheet Issues
A1: ID | B1: File | C1: CSV row | D1: Model / scope | E1: Column | F1: Severity | G1: Category | H1: Issue | I1: Fix | J1: Status
A2: 1 | B2: switching.csv | D2: (all rows) | E2: (new column) | F2: High | G2: Schema | H2: No lifecycle column; End-of-Sale models cannot be badged or excluded | I2: Add lifecycle, eos_announced, last_order, ldos, replacement_pid, eol_bulletin_url | J2: Open
A3: 2 | B3: switching.csv | D3: (all rows) | E3: (new columns) | F3: High | G3: Schema | H3: No Turkish text, series explainer, recommended flag, added_date or last_verified | I3: Add name_tr, summary_tr, good_for_tr, recommended, recommended_why_tr, added_date, last_verified, source_url | J3: Open
A4: 3 | B4: switching.csv | D4: 64 models (C9300, C9300X, C9300-M, C9200, C9350, C9400, C9600, C9610 …) | E4: Uplink Speed | F4: High | G4: Filter logic | H4: Uplink Speed = "Modular" never matches any uplink button, so every modular-uplink switch vanishes when an uplink filter is used | I4: Add uplink_gbps listing the speeds reachable with supported network modules, e.g. [1,10,25,40,100] | J4: Open
A5: 4 | B5: switching.csv | D5: C9400X-SUP-2, C9400X-SUP-2XL | E5: (missing rows) | F5: High | G5: Missing data | H5: Replacement supervisors for the End-of-Sale SUP-1/1XL are not in the data, so C9400 chassis cannot be configured | I5: Add both supervisors with compatibility to C9404R/C9407R/C9410R | J5: Open
A6: 5 | B6: switching.csv | C6: 26 | D6: MS210-24-HW | E6: Lifecycle | F6: High | G6: Lifecycle | H6: End-of-Sale since 2026-04-30; still listed as a normal model | I6: Move to "Eski modeller"; replacement: MS130 / MS150 (confirm per model) | J6: Open
A7: 6 | B7: switching.csv | C7: 27 | D7: MS210-24P-HW | E7: Lifecycle | F7: High | G7: Lifecycle | H7: End-of-Sale since 2026-04-30; still listed as a normal model | I7: Move to "Eski modeller"; replacement: MS130 / MS150 (confirm per model) | J7: Open
A8: 7 | B8: switching.csv | C8: 28 | D8: MS210-48-HW | E8: Lifecycle | F8: High | G8: Lifecycle | H8: End-of-Sale since 2026-04-30; still listed as a normal model | I8: Move to "Eski modeller"; replacement: MS130 / MS150 (confirm per model) | J8: Open
A9: 8 | B9: switching.csv | C9: 29 | D9: MS210-48LP-HW | E9: Lifecycle | F9: High | G9: Lifecycle | H9: End-of-Sale since 2026-04-30; still listed as a normal model | I9: Move to "Eski modeller"; replacement: MS130 / MS150 (confirm per model) | J9: Open
A10: 9 | B10: switching.csv | C10: 30 | D10: MS210-48FP-HW | E10: Lifecycle | F10: High | G10: Lifecycle | H10: End-of-Sale since 2026-04-30; still listed as a normal model | I10: Move to "Eski modeller"; replacement: MS130 / MS150 (confirm per model) | J10: Open
A11: 10 | B11: switching.csv | C11: 31 | D11: MS450-12-HW | E11: Lifecycle | F11: High | G11: Lifecycle | H11: End-of-Sale announced, last order 2026-10-29; no lifecycle field to show it | I11: Set lifecycle=eos_announced, last_order=2026-10-29, replacement=C9500-32QC | J11: Open
A12: 11 | B12: switching.csv | C12: 222 | D12: C9400-SUP-1 | E12: Lifecycle | F12: High | G12: Lifecycle | H12: End-of-Sale since 2025-04-30; still listed as a normal model | I12: Move to "Eski modeller"; replacement: C9400X-SUP-2 / C9400X-SUP-2XL (missing from data) | J12: Open
A13: 12 | B13: switching.csv | C13: 223 | D13: C9400-SUP-1XL | E13: Lifecycle | F13: High | G13: Lifecycle | H13: End-of-Sale since 2025-04-30; still listed as a normal model | I13: Move to "Eski modeller"; replacement: C9400X-SUP-2 / C9400X-SUP-2XL (missing from data) | J13: Open
A14: 13 | B14: switching.csv | C14: 238 | D14: C9500X-28C8D | E14: Downlink Port Count | F14: High | G14: Filter logic | H14: 28 ports fall between the 24 and 48+ buckets; model disappears whenever a port filter is on | I14: Store port count as a number; use buckets ≤8 / 9–16 / 17–28 / 29–47 / 48+ | J14: Open
A15: 14 | B15: switching.csv | C15: 240 | D15: C9500-32C | E15: Downlink Port Count | F15: High | G15: Filter logic | H15: 32 ports fall between the 24 and 48+ buckets; model disappears whenever a port filter is on | I15: Store port count as a number; use buckets ≤8 / 9–16 / 17–28 / 29–47 / 48+ | J15: Open
A16: 15 | B16: switching.csv | C16: 241 | D16: C9500-32QC | E16: Downlink Port Count | F16: High | G16: Filter logic | H16: 32 ports fall between the 24 and 48+ buckets; model disappears whenever a port filter is on | I16: Store port count as a number; use buckets ≤8 / 9–16 / 17–28 / 29–47 / 48+ | J16: Open
A17: 16 | B17: switching.csv | C17: 244 | D17: C9500-16X | E17: Lifecycle | F17: High | G17: Lifecycle | H17: End-of-Sale since 2026-04-30; still listed as a normal model | I17: Move to "Eski modeller"; replacement: C9500-24Y4C (NMs: none) | J17: Open
... A20: 19 | B20: switching.csv | C20: 247 | D20: C9500-NM-8X | E20: Lifecycle | F20: High | G20: Lifecycle | H20: End-of-Sale since 2026-04-30; still listed as a normal model | I20: Move to "Eski modeller"; replacement: C9500-24Y4C (NMs: none) | J20: Open
A21: 20 | B21: switching.csv | D21: 137 models | E21: Unified Architecture | F21: Medium | G21: Verify | H21: "Yes" on C9300/C9300L/C9200L/C9500/C9350 and -M rows; the toggle promises a unified-licence management pivot | I21: Confirm which PIDs support the unified licence/management mode and store as management: [on_prem, cloud] | J21: Open
A22: 21 | B22: switching.csv | C22: 81 | D22: C1200-8T-D | E22: Uplink Speed | F22: Medium | G22: Missing data | H22: Uplink Speed blank; excluded by any uplink filter | I22: Fill from datasheet (or "none" for fixed-port models without dedicated uplinks) | J22: Open
A23: 22 | B23: switching.csv | C23: 97 | D23: C1300-8T-E-2G | E23: Stacking / Features | F23: Medium | G23: Consistency | H23: Stacking column says Yes but the Features list (which the filter reads) omits it | I23: Confirm against Cisco's C1300 stacking SKU list, then make both agree (one field only) | J23: Open
A24: 23 | B24: switching.csv | C24: 98 | D24: C1300-8P-E-2G | E24: Stacking / Features | F24: Medium | G24: Consistency | H24: Stacking column says Yes but the Features list (which the filter reads) omits it | I24: Confirm against Cisco's C1300 stacking SKU list, then make both agree (one field only) | J24: Open
A25: 24 | B25: switching.csv | C25: 99 | D25: C1300-8FP-2G | E25: Stacking / Features | F25: Medium | G25: Consistency | H25: Stacking column says Yes but the Features list (which the filter reads) omits it | I25: Confirm against Cisco's C1300 stacking SKU list, then make both agree (one field only) | J25: Open
A26: 25 | B26: switching.csv | C26: 100 | D26: C1300-16T-2G | E26: Stacking / Features | F26: Medium | G26: Consistency | H26: Stacking column says Yes but the Features list (which the filter reads) omits it | I26: Confirm against Cisco's C1300 stacking SKU list, then make both agree (one field only) | J26: Open
A27: 26 | B27: switching.csv | C27: 101 | D27: C1300-16P-2G | E27: Stacking / Features | F27: Medium | G27: Consistency | H27: Stacking column says Yes but the Features list (which the filter reads) omits it | I27: Confirm against Cisco's C1300 stacking SKU list, then make both agree (one field only) | J27: Open
A28: 27 | B28: switching.csv | C28: 102 | D28: C1300-16FP-2G | E28: Stacking / Features | F28: Medium | G28: Consistency | H28: Stacking column says Yes but the Features list (which the filter reads) omits it | I28: Confirm against Cisco's C1300 stacking SKU list, then make both agree (one field only) | J28: Open
A29: 28 | B29: switching.csv | C29: 103 | D29: C1300-24T-4G | E29: Stacking / Features | F29: Medium | G29: Consistency | H29: Stacking column says Yes but the Features list (which the filter reads) omits it | I29: Confirm against Cisco's C1300 stacking SKU list, then make both agree (one field only) | J29: Open
A30: 29 | B30: switching.csv | C30: 104 | D30: C1300-24P-4G | E30: Stacking / Features | F30: Medium | G30: Consistency | H30: Stacking column says Yes but the Features list (which the filter reads) omits it | I30: Confirm against Cisco's C1300 stacking SKU list, then make both agree (one field only) | J30: Open
A31: 30 | B31: switching.csv | C31: 105 | D31: C1300-24FP-4G | E31: Stacking / Features | F31: Medium | G31: Consistency | H31: Stacking column says Yes but the Features list (which the filter reads) omits it | I31: Confirm against Cisco's C1300 stacking SKU list, then make both agree (one field only) | J31: Open
A32: 31 | B32: switching.csv | C32: 106 | D32: C1300-48T-4G | E32: Stacking / Features | F32: Medium | G32: Consistency | H32: Stacking column says Yes but the Features list (which the filter reads) omits it | I32: Confirm against Cisco's C1300 stacking SKU list, then make both agree (one field only) | J32: Open
A33: 32 | B33: switching.csv | C33: 107 | D33: C1300-48P-4G | E33: Stacking / Features | F33: Medium | G33: Consistency | H33: Stacking column says Yes but the Features list (which the filter reads) omits it | I33: Confirm against Cisco's C1300 stacking SKU list, then make both agree (one field only) | J33: Open
... A55: 54 | B55: switching.csv | C55: 358 | D55: CBS110-24PP | E55: Uplink Speed | F55: Medium | G55: Missing data | H55: Uplink Speed blank; excluded by any uplink filter | I55: Fill from datasheet (or "none" for fixed-port models without dedicated uplinks) | J55: Open
A56: 55 | B56: switching.csv | C56: 35 rows | D56: (rows using "Layer 2 Access") | E56: Layer3 support | F56: Medium | G56: Data quality | H56: Two spellings for the same value: "L2 Access" (75) and "Layer 2 Access" (35) | I56: One vocabulary: unmanaged / l2 / l3_basic / l3_full | J56: Open
A57: 56 | B57: switching.csv | D57: (feature tokens) | E57: Features | F57: Low | G57: Data quality | H57: Tokens with no filter button or mixed case: "rugged" (58), "DC Power"/"DC power" (39), "smart managed" (16), "unmanaged" (7) | I57: Controlled feature list; case-insensitive build check | J57: Open
A58: 57 | B58: switching.csv | D58: Network modules, line cards, IEM modules | E58: Supertype | F58: Low | G58: Schema | H58: Same module repeated under several Supertypes (e.g. C9300-NM-* under C9300 and 9300-M) to fake a compatibility link | I58: Separate compatibility table: module_pid ↔ chassis/series | J58: Open
A59: 58 | B59: switching.csv | C59: 189 | D59: BLANK (C9300 and C9300X) | E59: Model | F59: Low | G59: Data quality | H59: Two different rows share the model name "BLANK" | I59: Use the real PIDs C9300-NM-BLANK and C9300X-NM-BLANK | J59: Open
A60: 59 | B60: switching.csv | C60: 219 | D60: C9404R | E60: Stacking / Features | F60: Low | G60: Consistency | H60: Chassis lists "Stacking" in Features while Stacking column is No | I60: Remove from Features (chassis use StackWise Virtual, a separate feature) | J60: Open
A61: 60 | B61: switching.csv | C61: 220 | D61: C9407R | E61: Stacking / Features | F61: Low | G61: Consistency | H61: Chassis lists "Stacking" in Features while Stacking column is No | I61: Remove from Features (chassis use StackWise Virtual, a separate feature) | J61: Open
A62: 61 | B62: switching.csv | C62: 221 | D62: C9410R | E62: Stacking / Features | F62: Low | G62: Consistency | H62: Chassis lists "Stacking" in Features while Stacking column is No | I62: Remove from Features (chassis use StackWise Virtual, a separate feature) | J62: Open
A63: 62 | B63: switching.csv | C63: 248 | D63: C9606R | E63: Stacking / Features | F63: Low | G63: Consistency | H63: Chassis lists "Stacking" in Features while Stacking column is No | I63: Remove from Features (chassis use StackWise Virtual, a separate feature) | J63: Open
...

Sheet Lifecycle
A1: File | B1: Models | C1: Verified status | D1: End of sale (last order) | E1: Last date of support | F1: Replacement | G1: Action | H1: Source
A2: routers.csv | B2: ISR1100-4G, ISR1100-4GLTEGB, ISR1100-6G, ISR1100X-4G, ISR1100X-6G | C2: End-of-Sale (past) | D2: 2026-07-28 | F2: Catalyst 8100-G2 secure routers | G2: Remove → Eski modeller | H2: https://www.cisco.com/c/en/us/products/collateral/routers/1000-series-integrated-services-routers-isr/select-isr1100-product-eol.html
A3: routers.csv | B3: C1101-4P, C1101-4PLTEP, C1109-2PLTEGB | C3: End-of-Sale (past) | D3: 2026-07-28 | F3: C1121-4P / C1121-4PLTEP | G3: Remove → Eski modeller | H3: https://www.cisco.com/c/en/us/products/collateral/routers/1000-series-integrated-services-routers-isr/select-isr-1101-1109-series-routers-eol.html
A4: routers.csv | B4: C1111-4P, C1111-4P-DNA, C1111-8P, C1111-8P-DNA, C1111X-8P | C4: End-of-Sale (past) | D4: 2026-07-28 | F4: C1121-4P / C1121-8P / C1121X-8P | G4: Remove → Eski modeller | H4: https://www.cisco.com/c/en/us/products/collateral/routers/1000-series-integrated-services-routers-isr/isr-1111-series-ethernet-routers-eol.html
A5: routers.csv | B5: C921-4P, C921-4PLTEGB, C926-4P, C927-4P, C927-4PM, C927-4PLTEGB, C931-4P | C5: End-of-Sale (past) | D5: 2026-07-28 | F5: C1121 / Catalyst 8100-G2 | G5: Remove → Eski modeller | H5: https://www.cisco.com/c/en/us/products/collateral/routers/900-series-integrated-services-routers-isr/isr-900-series-routers-licenses-accessories-eol.html
A6: routers.csv | B6: C8300-1N1S-4T2X, C8300-1N1S-6T | C6: EoS announced | D6: 2027-01-31 | E6: 2032-01-31 | F6: C8375-E-G2 | G6: Keep with badge; exclude from selector | H6: https://www.cisco.com/c/en/us/products/collateral/networking/sdwan-routers/catalyst-8000-edge-platforms/catalyst-c8500l-8s4x-4t2x-c8300-1n1s-6t-eol.html
A7: routers.csv | B7: C8500L-8S4X | C7: EoS announced | D7: 2027-01-31 | E7: 2032-01-31 | F7: C8475-G2 | G7: Keep with badge; exclude from selector | H7: https://www.cisco.com/c/en/us/products/collateral/networking/sdwan-routers/catalyst-8000-edge-platforms/catalyst-c8500l-8s4x-4t2x-c8300-1n1s-6t-eol.html
A8: routers.csv | B8: C8500-12X, C8500-12X4QC | C8: EoS announced | D8: 2027-01-31 | F8: Catalyst 8500-G2 (verify per bulletin) | G8: Keep with badge; exclude from selector | H8: https://www.cisco.com/c/en/us/products/collateral/networking/sdwan-routers/catalyst-8000-edge-platforms/catalyst-c8500-12x-c8500-12x4qc-eol.html
A9: routers.csv | B9: C8200-1N-4T | C9: EoS announced | D9: 2027-07-31 | E9: 2032-07-31 | F9: C8235-E-G2 | G9: Keep with badge; exclude from selector | H9: https://www.cisco.com/c/en/us/products/collateral/networking/sdwan-routers/catalyst-8000-edge-platforms/catalyst-c8300-2n2s-4t2x-6t-1n-4t-c8200l-eol.html
A10: routers.csv | B10: C8200L-1N-4T | C10: EoS announced | D10: 2027-07-31 | E10: 2032-07-31 | F10: C8231-E-G2 | G10: Keep with badge; exclude from selector | H10: https://www.cisco.com/c/en/us/products/collateral/networking/sdwan-routers/catalyst-8000-edge-platforms/catalyst-c8300-2n2s-4t2x-6t-1n-4t-c8200l-eol.html
A11: routers.csv | B11: C8300-2N2S-4T2X, C8300-2N2S-6T | C11: EoS announced | D11: 2027-07-31 | E11: 2032-07-31 | F11: None listed by Cisco | G11: Keep with badge; exclude from selector | H11: https://www.cisco.com/c/en/us/products/collateral/networking/sdwan-routers/catalyst-8000-edge-platforms/catalyst-c8300-2n2s-4t2x-6t-1n-4t-c8200l-eol.html
A12: routers.csv | B12: C8500-20X6C | C12: EoS announced | D12: 2027-07-31 | F12: Catalyst 8500-G2 (verify per bulletin) | G12: Keep with badge; exclude from selector | H12: https://www.cisco.com/c/en/us/products/collateral/networking/sdwan-routers/catalyst-8000-edge-platforms/catalyst-c8500-20x6c-eol.html
A13: routers.csv | B13: MX84 | C13: End-of-Sale (past) | D13: 2021-10-31 | E13: 2026-10-31 | F13: MX85 | G13: Remove (support ends this month) | H13: https://documentation.meraki.com/General_Administration/Other_Topics/Product_End-of-Life_(EOL)_Policies
A14: routers.csv | B14: MX67C, MX68CW | C14: EoS announced | D14: 2026-11-27 | E14: 2031-11-30 | F14: C8111-C-G2-MX / C8121-CW-G2-MX | G14: Keep with badge; exclude from selector | H14: https://www.cisco.com/c/en/us/products/collateral/security/meraki-cloud-managed-security-appliances/mx67c-mx68cw-eol.html
A15: routers.csv | B15: Z3, Z3C | C15: End-of-Sale (past) | D15: 2024-09-04 | E15: 2029-09-04 | F15: Z4 / Z4C | G15: Remove → Eski modeller | H15: https://documentation.meraki.com/General_Administration/Other_Topics/Product_End-of-Life_(EOL)_Policies
A16: routers.csv | B16: C1109-4PLTE2P | C16: Current (excluded from EOL15650) | G16: Keep | H16: https://www.cisco.com/c/en/us/products/collateral/routers/1000-series-integrated-services-routers-isr/select-isr-1101-1109-series-routers-eol.html
A17: switching.csv | B17: MS210-24-HW, MS210-24P-HW, MS210-48-HW, MS210-48LP-HW, MS210-48FP-HW | C17: End-of-Sale (past) | D17: 2026-04-30 | E17: 2031-04-30 | F17: MS130 / MS150 (confirm per model) | G17: Remove → Eski modeller | H17: https://documentation.meraki.com/General_Administration/Other_Topics/Product_End-of-Life_(EOL)_Policies
A18: switching.csv | B18: MS450-12-HW | C18: EoS announced | D18: 2026-10-29 | E18: 2031-10-31 | F18: C9500-32QC | G18: Keep with badge until 29 Oct, then remove | H18: https://www.cisco.com/c/en/us/products/collateral/networking/switches/meraki-switches/meraki-ms450-12x40g-aggregation-switch-eol.html
A19: switching.csv | B19: C9500-16X, C9500-16X-2Q, C9500-NM-8X, C9500-NM-2Q | C19: End-of-Sale (past) | D19: 2026-04-30 | E19: 2031-04-30 | F19: C9500-24Y4C (NMs: none) | G19: Remove → Eski modeller | H19: https://www.cisco.com/c/en/us/products/collateral/switches/catalyst-9500-series-switches/c9500-16x-switch-nm-c9500-nm-8x-nm-2q-eol.html
A20: switching.csv | B20: C9400-SUP-1, C9400-SUP-1XL | C20: End-of-Sale (past) | D20: 2025-04-30 | E20: 2030-04-30 | F20: C9400X-SUP-2 / C9400X-SUP-2XL (missing from data) | G20: Remove; add SUP-2 rows | H20: https://www.cisco.com/c/en/us/products/collateral/switches/catalyst-9400-series-switches/catalyst-9400-series-supervisor-module-eol.html
A21: switching.csv | B21: CBS220 (16 models) | C21: Current (replacement in SF/SG220 bulletin) | G21: Keep; recheck yearly | H21: https://www.cisco.com/c/en/us/products/collateral/switches/small-business-220-series-smart-plus-switches/220-series-smart-switches-eol.html
A22: switching.csv | B22: CBS110 (7 models), C9200 (9 models + NMs), IE-1000 (4 models) | C22: Not verified | G22: Verify on cisco.com EoL pages
A23: wireless-data.csv | B23: C9105/C9115/C9120/C9130 (10 rows), MR36/MR36H/MR44/MR46/MR46E | C23: EoS announced (CSV correct) | D23: 2026-12-31 | E23: 2031-12-31 | F23: CW917x Wi-Fi 7 | G23: Keep with badge; exclude from selector | H23: https://documentation.meraki.com/General_Administration/Other_Topics/Product_End-of-Life_(EOL)_Policies
A24: wireless-data.csv | B24: Catalyst 9124AXI/D/E, Catalyst 9136I | C24: Current (not in Wi-Fi 6 indoor bulletin) | G24: Keep; confirm 9136I on cisco.com | H24: https://www.xsnet.com.au/blogs/news/cisco-wifi-6-access-point-eol
A25: wireless-data.csv | B25: CW9177I, CW9177D, CW9177E | C25: CSV says "Shipping Sep 2026" | G25: Re-check; set Current if shipping
A26: wireless-data.csv | B26: IW9167E/I/E-HZ, IW9165E/D | C26: Blank in CSV | G26: Fill lifecycle
A27: wireless-data.csv | B27: MR28, MR57, MR76, MR78, MR86 | C27: Current (not on Meraki EOL list) | G27: Keep | H27: https://documentation.meraki.com/General_Administration/Other_Topics/Product_End-of-Life_(EOL)_Policies
A28: DC-data.csv | B28: N9K-C9364C | C28: End-of-Sale (past) | D28: 2024-01-30 | E28: 2029-01-31 | F28: N9K-C9364C-GX (already in data) | G28: Remove → Eski modeller | H28: https://www.cisco.com/c/en/us/products/collateral/switches/nexus-9000-series-switches/nexus-9332c-9364c-fixed-spine-switch-eol.html
A29: DC-data.csv | B29: N3K-C3548P-XL, N3K-C3524P-XL | C29: Current (replacements in 3524-X/3548-X bulletin) | G29: Keep; recheck yearly | H29: https://www.cisco.com/c/en/us/products/collateral/switches/nexus-3000-series-switches/nexus-3524-x-3548-x-eol.html
A30: DC-data.csv | B30: N9K-C9348GC-FXP, N9K-C93240YC-FX2, N9K-C93360YC-FX2, N9K-C93216TC-FX2, DS-C9148T, DS-C9132T, DS-C9396T | C30: Not verified | G30: Verify (third-party trackers list FXP Cisco ONE bundle as EoS)
A31: dc-modules-data.csv | B31: N9K-X9736C-FX | C31: EoS announced | D31: 2027-07-31 | E31: 2032-07-31 | F31: N9K-X9736C-FX3 (in data) | G31: Keep with badge | H31: https://www.cisco.com/c/en/us/products/collateral/switches/nexus-9000-series-switches/n9500-cloud-scale-line-cards-eol.html
A32: dc-modules-data.csv | B32: N9K-X9732C-FX | C32: EoS announced | D32: 2027-01-29 | E32: 2032-01-31 | F32: N9K-X9736C-FX3 (in data) | G32: Keep with badge | H32: https://www.cisco.com/c/en/us/products/collateral/switches/nexus-9000-series-switches/n9500-cloud-n9k-x9732c-fx-100g-eth-card-eol.pdf
A33: dc-modules-data.csv | B33: N9K-X97160YC-EX, N9K-X9788TC-FX, N9K-C9504-FM-E, N9K-C9508-FM-E2, N9K-C9516-FM-E2, N9K-X9636Q-R, DS-X9334-K9 | C33: Not verified | G33: Verify (EX-generation siblings X9732C-EX/X9736C-EX are EoS) | H33: https://www.cisco.com/c/en/us/products/collateral/switches/nexus-9000-series-switches/nexus-9500-100g-n9k-x9732c-ex-n9k-x9736c-ex-eol.html
A35: Dates from Cisco/Meraki EoL bulletins (Table 1). C9136I/C9124AX status from a secondary source (xsnet.com.au) summarising Cisco's March 2026 Wi-Fi 6 indoor bulletin; confirm on cisco.com. Router dates for ISR1000/900/C8000 were researched in earlier sessions from the bulletins linked.

Sheet Filter tests
A1: Page | B1: Old logic | C1: What happens with this data | D1: Models affected | E1: Fix in the new build
A2: Switching | B2: bucketPortCount: <8 / 9-23 / 24 / 48+ | C2: 25–47 ports return "Unknown"; C9500X-28C8D, C9500-32C, C9500-32QC disappear when any port filter is on. "<8" also includes 8. | D2: 3 | E2: Numeric "at least N ports" or buckets ≤8 / 9–16 / 17–28 / 29–47 / 48+
A3: Switching | B3: Uplink filter = exact match on "1Gbps", "10Gbps"… | C3: Uplink Speed "Modular" (64) or blank (22) never matches, so C9300/C9300X/C9200/C9350 and chassis vanish under any uplink filter. | D3: 86 | E3: uplink_gbps array including module-reachable speeds
A4: Switching | B4: Layer 3 button = "Full L3" only | C4: "Basic L3" (49) is not selectable; L2 has two spellings. | D4: 49 | E4: Three-way selector: L2 / Basic L3 / Full L3
A5: Switching | B5: Features use every() (AND); other groups some() (OR) | C5: Picking two features means "must have both", unlike every other group, with no hint in the UI. | D5: All | E5: OR within a group, AND across groups; label features "must have"
A6: Wireless | B6: bandTokens splits on "/" and expects "2.4", "5", "6" | C6: IW9165E/D "5-Ghz / 6-Ghz" yields no bands; both disappear under any band filter. | D6: 2 | E6: bands_ghz array in data
A7: Wireless | B7: Antenna filter uses every() | C7: Selecting Internal + External requires both on one AP → only IW9165D survives. | D7: All | E7: OR within the group
A8: Wireless | B8: uplinkTokens regex | C8: Works on this data, but "1/2.5/5G" style strings would lose 1G and 5G; fragile. | D8: 0 | E8: uplink_gbps array
A9: Wireless | B9: poeSet: substring "at"/"bt" | C9: Works on this data; any note containing "at" (e.g. "rated") would match 802.3at. | D9: 0 | E9: poe_min, poe_full fields
A10: Wireless | B10: Management bucket from text | C10: "Cisco Business" → "Other": CBW models only appear under ALL. | D10: 2 | E10: management array incl. embedded
A11: Wireless | B11: antennasFor: fuzzy substring | C11: "MR46" is a substring of "MR46E"; harmless today only because MR46 is internal-antenna. | D11: 0 | E11: Exact join table
A12: Routing | B12: Throughput query compares numbers parsed from text | C12: 44 models with blank Throughput are excluded from every throughput query. | D12: 44 | E12: Numeric fields; "n/a" excluded explicitly with a note
A13: Routing | B13: compatModulesFor: substring on "Supported router models" | C13: "C8200" attaches C8200 modules to C8200-G2 routers; "ISR1000" attaches P-LTEA-EA to 38 ISR1000 models. | D13: 55 | E13: module_pid ↔ router_pid table
A14: Data Center | B14: speedTokens on Downlink Speeds | C14: 15 leaves list "; 40/100G uplink" inside the downlink field and "100M" parses as 100G → false matches on the 100G downlink filter. | D14: 15 | E14: downlink_gbps / uplink_gbps arrays
A15: Data Center | B15: Feature filter = substring | C15: All 10 MDS switches contain "(no VXLAN/EVPN)" and match the VXLAN and EVPN filters. | D15: 10 | E15: Boolean feature flags
